开卡群(-1001603206320)消息：我来了
开卡群(-1001603206320)消息：groupCode
345275
文件下载成功:gua_opencard211.js
git push
开卡群(-1001603206320)消息：删除 gua_opencard211.js
git push
Traceback (most recent call last):
  File "/usr/lib/python3.8/site-packages/urllib3/connectionpool.py", line 670, in urlopen
    httplib_response = self._make_request(
  File "/usr/lib/python3.8/site-packages/urllib3/connectionpool.py", line 381, in _make_request
    self._validate_conn(conn)
  File "/usr/lib/python3.8/site-packages/urllib3/connectionpool.py", line 976, in _validate_conn
    conn.connect()
  File "/usr/lib/python3.8/site-packages/urllib3/connection.py", line 361, in connect
    self.sock = ssl_wrap_socket(
  File "/usr/lib/python3.8/site-packages/urllib3/util/ssl_.py", line 377, in ssl_wrap_socket
    return context.wrap_socket(sock, server_hostname=server_hostname)
  File "/usr/lib/python3.8/ssl.py", line 500, in wrap_socket
    return self.sslsocket_class._create(
  File "/usr/lib/python3.8/ssl.py", line 1040, in _create
    self.do_handshake()
  File "/usr/lib/python3.8/ssl.py", line 1309, in do_handshake
    self._sslobj.do_handshake()
ssl.SSLEOFError: EOF occurred in violation of protocol (_ssl.c:1131)

During handling of the above exception, another exception occurred:

Traceback (most recent call last):
  File "/usr/lib/python3.8/site-packages/requests/adapters.py", line 440, in send
    resp = conn.urlopen(
  File "/usr/lib/python3.8/site-packages/urllib3/connectionpool.py", line 724, in urlopen
    retries = retries.increment(
  File "/usr/lib/python3.8/site-packages/urllib3/util/retry.py", line 439, in increment
    raise MaxRetryError(_pool, url, error or ResponseError(cause))
urllib3.exceptions.MaxRetryError: HTTPSConnectionPool(host='api.telegram.org', port=443): Max retries exceeded with url: /bot5497496239:AAH7m475zGNAkxiW6tWcqFYWJwUklf5VDI4/getUpdates?offset=740159448 (Caused by SSLError(SSLEOFError(8, 'EOF occurred in violation of protocol (_ssl.c:1131)')))

During handling of the above exception, another exception occurred:

Traceback (most recent call last):
  File "tgBot.py", line 119, in <module>
    getUpdates(updateId)
  File "tgBot.py", line 32, in getUpdates
    response = requests.request("GET", url, data=None, headers=None,proxies=proxies,verify=False)
  File "/usr/lib/python3.8/site-packages/requests/api.py", line 61, in request
    return session.request(method=method, url=url, **kwargs)
  File "/usr/lib/python3.8/site-packages/requests/sessions.py", line 529, in request
    resp = self.send(prep, **send_kwargs)
  File "/usr/lib/python3.8/site-packages/requests/sessions.py", line 645, in send
    r = adapter.send(request, **kwargs)
  File "/usr/lib/python3.8/site-packages/requests/adapters.py", line 517, in send
    raise SSLError(e, request=request)
requests.exceptions.SSLError: HTTPSConnectionPool(host='api.telegram.org', port=443): Max retries exceeded with url: /bot5497496239:AAH7m475zGNAkxiW6tWcqFYWJwUklf5VDI4/getUpdates?offset=740159448 (Caused by SSLError(SSLEOFError(8, 'EOF occurred in violation of protocol (_ssl.c:1131)')))
